<?xml version="1.0" encoding="utf-8"?>
<robot>
  <link
    name="base_link">
    <!-- <inertial>
      <origin
        xyz="-9.81410393552373E-06 -0.0460000689343235 -0.0065295158451983"
        rpy="0 0 0" />
      <mass
        value="0.335467320988356" />
      <inertia
        ixx="4.37751934245478E-05"
        ixy="-7.25114187919924E-08"
        ixz="-1.8551473383786E-07"
        iyy="3.79746167195594E-05"
        iyz="-1.48426357415501E-05"
        izz="5.80238931250525E-06" />
    </inertial> -->
    <visual>
      <origin
        xyz="0 0 0"
        rpy="0 0 0" />
      <geometry>
        <mesh
          filename="package://gummi_base_$(env ROS_GUMMI_BASE)/meshes/base_Link1.stl" />
      </geometry>
      <material
        name="">
        <color
          rgba="0.792156862745098 0.819607843137255 0.933333333333333 1" />
      </material>
    </visual>
    <collision>
      <origin
        xyz="0 0 0"
        rpy="0 0 0" />
      <geometry>
        <mesh
          filename="package://gummi_base_$(env ROS_GUMMI_BASE)/meshes/base_Link1.stl" />
      </geometry>
    </collision>
  </link>
  <link
    name="shoulder_preroll">
    <inertial>
      <origin
        xyz="-2.1762E-05 -0.0041376 0.031717"
        rpy="0 0 0" />
      <mass
        value="0.77225" />
      <inertia
        ixx="0.0026527"
        ixy="1.2427E-07"
        ixz="5.0677E-07"
        iyy="0.003032"
        iyz="4.4108E-05"
        izz="0.0012294" />
    </inertial>
    <visual>
      <origin
        xyz="0 0 0"
        rpy="0 0 0" />
      <geometry>
        <mesh
          filename="package://gummi_base_$(env ROS_GUMMI_BASE)/meshes/j1_Link.stl" />
      </geometry>
      <material
        name="">
        <color
          rgba="0.79216 0.81961 0.93333 1" />
      </material>
    </visual>
    <collision>
      <origin
        xyz="0 0 0"
        rpy="0 0 0" />
      <geometry>
        <mesh
          filename="package://gummi_base_$(env ROS_GUMMI_BASE)/meshes/j1_Link_CH.stl" />
      </geometry>
    </collision>
  </link>
  <joint
    name="shoulder_yaw"
    type="revolute">
    <origin
      xyz="0 0 0"
      rpy="0 0 0" />
    <parent
      link="base_link" />
    <child
      link="shoulder_preroll" />
    <axis
      xyz="0 0 1" />
    <limit
      lower="-0.75"
      upper="1"
      effort="0"
      velocity="0" />
  </joint>
  <link
    name="shoulder">
    <inertial>
      <origin
        xyz="-6.6912E-05 -0.10412 4.2145E-06"
        rpy="0 0 0" />
      <mass
        value="0.32611" />
      <inertia
        ixx="0.00024984"
        ixy="-1.3E-06"
        ixz="1.74E-07"
        iyy="7.3364E-05"
        iyz="8.2134E-08"
        izz="0.0003232" />
    </inertial>
    <visual>
      <origin
        xyz="0 0 0"
        rpy="0 0 0" />
      <geometry>
        <mesh
          filename="package://gummi_base_$(env ROS_GUMMI_BASE)/meshes/j2_Link.stl" />
      </geometry>
      <material
        name="">
        <color
          rgba="0.79216 0.81961 0.93333 1" />
      </material>
    </visual>
    <collision>
      <origin
        xyz="0 0 0"
        rpy="0 0 0" />
      <geometry>
        <mesh
          filename="package://gummi_base_$(env ROS_GUMMI_BASE)/meshes/j2_Link_CH.stl" />
      </geometry>
    </collision>
  </link>
  <joint
    name="shoulder_roll"
    type="revolute">
    <origin
      xyz="0 -0.065 0.1265"
      rpy="-1.57079632679 3.14159265359 0" />
    <parent
      link="shoulder_preroll" />
    <child
      link="shoulder" />
    <axis
      xyz="0 0 -1" />
    <limit
      lower="-0.95"
      upper="2.3"
      effort="0"
      velocity="0" />
  </joint>
  <link
    name="upperarm_preroll">
    <inertial>
      <origin
        xyz="0.031774 -0.0098005 -0.046115"
        rpy="0 0 0" />
      <mass
        value="0.11889" />
      <inertia
        ixx="4.0724E-05"
        ixy="7.0589E-07"
        ixz="1.4611E-05"
        iyy="6.3279E-05"
        iyz="6.4487E-07"
        izz="2.3476E-05" />
    </inertial>
    <visual>
      <origin
        xyz="0 0 0"
        rpy="0 0 0" />
      <geometry>
        <mesh
          filename="package://gummi_base_$(env ROS_GUMMI_BASE)/meshes/j3_Link.stl" />
      </geometry>
      <material
        name="">
        <color
          rgba="0.79216 0.81961 0.93333 1" />
      </material>
    </visual>
    <collision>
      <origin
        xyz="0 0 0"
        rpy="0 0 0" />
      <geometry>
        <mesh
          filename="package://gummi_base_$(env ROS_GUMMI_BASE)/meshes/j3_Link_CH.stl" />
      </geometry>
    </collision>
  </link>
  <joint
    name="shoulder_pitch"
    type="revolute">
    <origin
      xyz="-0.019 0 -0.054"
      rpy="-1.57079632679 0 1.57079632679" />
    <parent
      link="shoulder" />
    <child
      link="upperarm_preroll" />
    <axis
      xyz="0 0 -1" />
    <limit
      lower="-0.15"
      upper="1.1"
      effort="0"
      velocity="0" />
  </joint>
  <link
    name="upperarm">
    <inertial>
      <origin
        xyz="-0.0024737 -8.3239E-05 -0.1319"
        rpy="0 0 0" />
      <mass
        value="0.26501" />
      <inertia
        ixx="0.00079812"
        ixy="-7.2143E-08"
        ixz="-4.087E-05"
        iyy="0.0007849"
        iyz="-1.9447E-06"
        izz="2.1965E-05" />
    </inertial>
    <visual>
      <origin
        xyz="0 0 0"
        rpy="0 0 0" />
      <geometry>
        <mesh
          filename="package://gummi_base_$(env ROS_GUMMI_BASE)/meshes/j4_Link.stl" />
      </geometry>
      <material
        name="">
        <color
          rgba="0.79216 0.81961 0.93333 1" />
      </material>
    </visual>
    <collision>
      <origin
        xyz="0 0 0"
        rpy="0 0 0" />
      <geometry>
        <mesh
          filename="package://gummi_base_$(env ROS_GUMMI_BASE)/meshes/j4_Link_CH.stl" />
      </geometry>
    </collision>
  </link>
  <joint
    name="upperarm_roll"
    type="revolute">
    <origin
      xyz="-0.0355 0.00999 0.0145"
      rpy="-1.57079632679 0 -1.57079632679" />
    <parent
      link="upperarm_preroll" />
    <child
      link="upperarm" />
    <axis
      xyz="0 0 -1" />
    <limit
      lower="-1.56"
      upper="1.56"
      effort="0"
      velocity="0" />
  </joint>
  <link
    name="lowerarm_preroll_u">
    <inertial>
      <origin
        xyz="0.030339 -0.01865 -0.003795"
        rpy="0 0 0" />
      <mass
        value="0.034447" />
      <inertia
        ixx="0"
        ixy="0"
        ixz="0"
        iyy="0"
        iyz="0"
        izz="0" />
    </inertial>
    <visual>
      <origin
        xyz="0 0 0"
        rpy="0 0 0" />
      <geometry>
        <mesh
          filename="package://gummi_base_$(env ROS_GUMMI_BASE)/meshes/lowerarm_preroll_u.stl" />
      </geometry>
      <material
        name="">
        <color
          rgba="0.79216 0.81961 0.93333 1" />
      </material>
    </visual>
    <collision>
      <origin
        xyz="0 0 0"
        rpy="0 0 0" />
      <geometry>
        <mesh
          filename="package://gummi_base_$(env ROS_GUMMI_BASE)/meshes/lowerarm_preroll_u_CH.stl" />
      </geometry>
    </collision>
  </link>
  <joint
    name="elbow"
    type="revolute">
    <origin
      xyz="-0.021 0.003 -0.2338"
      rpy="3.14159265359 1.57079632679 0" />
    <parent
      link="upperarm" />
    <child
      link="lowerarm_preroll_u" />
    <axis
      xyz="0 0 1" />
    <limit
      lower="-0.75"
      upper="0.35"
      effort="0"
      velocity="0" />
  </joint>
</robot>
